Workbook

Sheet Read Me
A1: Mobile Number Masking - Component Register
A2: As of 2026-10-06
A4: Item | B4: Details
A5: Purpose | B5: Single register of every component of the Mobile Number Masking project: new components, existing components that change, backups, manual steps, tests, and the full production deployment list. Kept until the project completes.
A6: As of | B6: 2026-10-06
A7: Source | B7: Local git repository (branches ejjigiripraveen/v1.x.0-*), CHANGELOG.md, ROADMAP.md. Sandbox deploy IDs from sandbox gsquaregroup--prodreplic.
A8: Status colours | B8: Green = deployed / done / backed up Â· Yellow = built locally / pending approval Â· Grey = planned / not started Â· Orange = conditional / vendor Â· Blue = sandbox only / manual
A9: Production list | B9: Sheet "Prod Deployment List" is generated from "New Components" and "Existing Components" (rows needed in production) plus the production manual steps, in deploy order. Update the Prod Status column as you deploy.
A10: Rule | B10: Existing components are changed only after approval; original code is backed up first (sheet "Backups").
A11: Rule | B11: Sandbox first, then production pilot (1 SlashRTC + 1 360CTI + 1 MCube user), then everyone.

Sheet Summary
A1: Summary by Part
A2: Counts are formulas over the other sheets
A4: Part | B4: Version | C4: Scope | D4: Status | E4: New components | F4: Existing components changed | G4: New deployed to sandbox | H4: Rows in prod list
A5: Part 1 | B5: v1.1.0 | C5: Foundations | D5: Deployed (Sandbox) | E5: =COUNTIFS('New Components'!$B:$B,A5) | F5: =COUNTIFS('Existing Components'!$B:$B,A5) | G5: =COUNTIFS('New Components'!$B:$B,A5,'New Components'!$I:$I,"Deployed*") | H5: =COUNTIFS('Prod Deployment List'!$B:$B,A5)
A6: Part 2 | B6: v1.2.0 | C6: Masked phone panel (POC users) | D6: Deployed (Sandbox) | E6: =COUNTIFS('New Components'!$B:$B,A6) | F6: =COUNTIFS('Existing Components'!$B:$B,A6) | G6: =COUNTIFS('New Components'!$B:$B,A6,'New Components'!$I:$I,"Deployed*") | H6: =COUNTIFS('Prod Deployment List'!$B:$B,A6)
A7: Part 3 | B7: v1.3.0 | C7: Dialer adapters MCube + SlashRTC (POC) | D7: Deployed (Sandbox) | E7: =COUNTIFS('New Components'!$B:$B,A7) | F7: =COUNTIFS('Existing Components'!$B:$B,A7) | G7: =COUNTIFS('New Components'!$B:$B,A7,'New Components'!$I:$I,"Deployed*") | H7: =COUNTIFS('Prod Deployment List'!$B:$B,A7)
A8: Part 4 | B8: v1.4.0 | C8: Lead creation with hidden numbers | D8: Deployed (Sandbox) | E8: =COUNTIFS('New Components'!$B:$B,A8) | F8: =COUNTIFS('Existing Components'!$B:$B,A8) | G8: =COUNTIFS('New Components'!$B:$B,A8,'New Components'!$I:$I,"Deployed*") | H8: =COUNTIFS('Prod Deployment List'!$B:$B,A8)
A9: Part 5 | B9: v1.5.0 | C9: Mask leaking screens (5a-5d deployed, call panels deferred D1) | D9: Deployed (Sandbox) - 5a to 5d | E9: =COUNTIFS('New Components'!$B:$B,A9) | F9: =COUNTIFS('Existing Components'!$B:$B,A9) | G9: =COUNTIFS('New Components'!$B:$B,A9,'New Components'!$I:$I,"Deployed*") | H9: =COUNTIFS('Prod Deployment List'!$B:$B,A9)
A10: Part 6 | B10: v1.6.0 | C10: Reveal + audit cleanup | D10: Planned | E10: =COUNTIFS('New Components'!$B:$B,A10) | F10: =COUNTIFS('Existing Components'!$B:$B,A10) | G10: =COUNTIFS('New Components'!$B:$B,A10,'New Components'!$I:$I,"Deployed*") | H10: =COUNTIFS('Prod Deployment List'!$B:$B,A10)
A11: Part 7 | B11: v1.7.0 | C11: Free-text auto-masking | D11: Planned | E11: =COUNTIFS('New Components'!$B:$B,A11) | F11: =COUNTIFS('Existing Components'!$B:$B,A11) | G11: =COUNTIFS('New Components'!$B:$B,A11,'New Components'!$I:$I,"Deployed*") | H11: =COUNTIFS('Prod Deployment List'!$B:$B,A11)
A12: Part 8 | B12: v1.8.0 | C12: Find by number | D12: Conditional | E12: =COUNTIFS('New Components'!$B:$B,A12) | F12: =COUNTIFS('Existing Components'!$B:$B,A12) | G12: =COUNTIFS('New Components'!$B:$B,A12,'New Components'!$I:$I,"Deployed*") | H12: =COUNTIFS('Prod Deployment List'!$B:$B,A12)
A13: Part 9 | B13: v1.9.0 | C13: Opportunity, Contact, documents | D13: Conditional | E13: =COUNTIFS('New Components'!$B:$B,A13) | F13: =COUNTIFS('Existing Components'!$B:$B,A13) | G13: =COUNTIFS('New Components'!$B:$B,A13,'New Components'!$I:$I,"Deployed*") | H13: =COUNTIFS('Prod Deployment List'!$B:$B,A13)
A14: Part 10 | B14: - | C14: Vendor deliveries | D14: Vendor | E14: =COUNTIFS('New Components'!$B:$B,A14) | F14: =COUNTIFS('Existing Components'!$B:$B,A14) | G14: =COUNTIFS('New Components'!$B:$B,A14,'New Components'!$I:$I,"Deployed*") | H14: =COUNTIFS('Prod Deployment List'!$B:$B,A14)
A15: Part 11 | B15: v2.0.0 | C15: Go-live access (masking ON) | D15: Planned | E15: =COUNTIFS('New Components'!$B:$B,A15) | F15: =COUNTIFS('Existing Components'!$B:$B,A15) | G15: =COUNTIFS('New Components'!$B:$B,A15,'New Components'!$I:$I,"Deployed*") | H15: =COUNTIFS('Prod Deployment List'!$B:$B,A15)
A16: Security fix | B16: optional | C16: MCube Named Credential | D16: Planned | E16: =COUNTIFS('New Components'!$B:$B,A16) | F16: =COUNTIFS('Existing Components'!$B:$B,A16) | G16: =COUNTIFS('New Components'!$B:$B,A16,'New Components'!$I:$I,"Deployed*") | H16: =COUNTIFS('Prod Deployment List'!$B:$B,A16)
A17: Total | E17: =SUM(E5:E16) | F17: =SUM(F5:F16) | G17: =SUM(G5:G16) | H17: =SUM(H5:H16)

Sheet New Components
A1: New Components
A2: Everything this project creates
A4: # | B4: Part | C4: Version | D4: Metadata Type | E4: API Name | F4: Parent / Object | G4: What it does | H4: Test class | I4: Status | J4: Sandbox Deploy ID / Record Id | K4: Needed in Production | L4: Notes
A5: 1 | B5: Part 1 | C5: v1.1.0 | D5: Custom Metadata Type | E5: Phone_Masking_Setting__mdt | G5: Masking settings: format, reveal seconds, retention, kill switches | I5: Deployed (Sandbox) | J5: 0Afft000000LO8zCAG | K5: Yes
A6: 2 | B6: Part 1 | C6: v1.1.0 | D6: Custom Field | E6: Visible_Prefix_Digits__c | F6: Phone_Masking_Setting__mdt | G6: Digits shown at start (2) | I6: Deployed (Sandbox) | J6: 0Afft000000LO8zCAG | K6: Yes
A7: 3 | B7: Part 1 | C7: v1.1.0 | D7: Custom Field | E7: Visible_Suffix_Digits__c | F7: Phone_Masking_Setting__mdt | G7: Digits shown at end (2) | I7: Deployed (Sandbox) | J7: 0Afft000000LO8zCAG | K7: Yes
A8: 4 | B8: Part 1 | C8: v1.1.0 | D8: Custom Field | E8: Mask_Character__c | F8: Phone_Masking_Setting__mdt | G8: Mask character (X) | I8: Deployed (Sandbox) | J8: 0Afft000000LO8zCAG | K8: Yes
A9: 5 | B9: Part 1 | C9: v1.1.0 | D9: Custom Field | E9: Country_Code_To_Strip__c | F9: Phone_Masking_Setting__mdt | G9: Country code removed (91) | I9: Deployed (Sandbox) | J9: 0Afft000000LO8zCAG | K9: Yes
A10: 6 | B10: Part 1 | C10: v1.1.0 | D10: Custom Field | E10: Reveal_Seconds__c | F10: Phone_Masking_Setting__mdt | G10: Reveal duration (30) | I10: Deployed (Sandbox) | J10: 0Afft000000LO8zCAG | K10: Yes
A11: 7 | B11: Part 1 | C11: v1.1.0 | D11: Custom Field | E11: Audit_Retention_Days__c | F11: Phone_Masking_Setting__mdt | G11: Audit retention (365) | I11: Deployed (Sandbox) | J11: 0Afft000000LO8zCAG | K11: Yes
A12: 8 | B12: Part 1 | C12: v1.1.0 | D12: Custom Field | E12: Resolve_Enabled__c | F12: Phone_Masking_Setting__mdt | G12: Kill switch: real number lookup on/off | I12: Deployed (Sandbox) | J12: 0Afft000000LO8zCAG | K12: Yes
A13: 9 | B13: Part 1 | C13: v1.1.0 | D13: Custom Field | E13: Audit_Enabled__c | F13: Phone_Masking_Setting__mdt | G13: Audit on/off | I13: Deployed (Sandbox) | J13: 0Afft000000LO8zCAG | K13: Yes
A14: 10 | B14: Part 1 | C14: v1.1.0 | D14: Custom Metadata Type | E14: Masked_Phone_Field__mdt | G14: Approved list of phone fields that may be dialed / revealed | I14: Deployed (Sandbox) | J14: 0Afft000000LO8zCAG | K14: Yes
A15: 11 | B15: Part 1 | C15: v1.1.0 | D15: Custom Field | E15: Object_API_Name__c | F15: Masked_Phone_Field__mdt | G15: Object, e.g. Lead | I15: Deployed (Sandbox) | J15: 0Afft000000LO8zCAG | K15: Yes
A16: 12 | B16: Part 1 | C16: v1.1.0 | D16: Custom Field | E16: Field_API_Name__c | F16: Masked_Phone_Field__mdt | G16: Field, e.g. Phone__c | I16: Deployed (Sandbox) | J16: 0Afft000000LO8zCAG | K16: Yes
A17: 13 | B17: Part 1 | C17: v1.1.0 | D17: Custom Field | E17: Display_Label__c | F17: Masked_Phone_Field__mdt | G17: Label in panel | I17: Deployed (Sandbox) | J17: 0Afft000000LO8zCAG | K17: Yes
A18: 14 | B18: Part 1 | C18: v1.1.0 | D18: Custom Field | E18: Sort_Order__c | F18: Masked_Phone_Field__mdt | G18: Display order | I18: Deployed (Sandbox) | J18: 0Afft000000LO8zCAG | K18: Yes
A19: 15 | B19: Part 1 | C19: v1.1.0 | D19: Custom Field | E19: Allow_Dial__c | F19: Masked_Phone_Field__mdt | G19: May be dialed | I19: Deployed (Sandbox) | J19: 0Afft000000LO8zCAG | K19: Yes
A20: 16 | B20: Part 1 | C20: v1.1.0 | D20: Custom Field | E20: Allow_Reveal__c | F20: Masked_Phone_Field__mdt | G20: May be revealed | I20: Deployed (Sandbox) | J20: 0Afft000000LO8zCAG | K20: Yes
A21: 17 | B21: Part 1 | C21: v1.1.0 | D21: Custom Field | E21: Active__c | F21: Masked_Phone_Field__mdt | G21: Active | I21: Deployed (Sandbox) | J21: 0Afft000000LO8zCAG | K21: Yes
A22: 18 | B22: Part 1 | C22: v1.1.0 | D22: Custom Metadata Record | E22: Phone_Masking_Setting.Default | F22: Phone_Masking_Setting__mdt | G22: Default settings record (2 / 2 / X / 91 / 30 / 365 / on / on) | I22: Deployed (Sandbox) | J22: 0Afft000000LO8zCAG | K22: Yes
A23: 19 | B23: Part 1 | C23: v1.1.0 | D23: Custom Metadata Record | E23: Masked_Phone_Field.Lead_Phone | F23: Masked_Phone_Field__mdt | G23: Approves Lead.Phone__c (Primary) | I23: Deployed (Sandbox) | J23: 0Afft000000LO8zCAG | K23: Yes
A24: 20 | B24: Part 1 | C24: v1.1.0 | D24: Custom Metadata Record | E24: Masked_Phone_Field.Lead_Secondary_Phone | F24: Masked_Phone_Field__mdt | G24: Approves Lead.Secondary_Phone__c (Secondary) | I24: Deployed (Sandbox) | J24: 0Afft000000LO8zCAG | K24: Yes
A25: 21 | B25: Part 1 | C25: v1.1.0 | D25: Custom Object | E25: Phone_Access_Audit__c | G25: Audit trail of every dial / reveal / search (masked number only); Private | I25: Deployed (Sandbox) | J25: 0Afft000000LO8zCAG | K25: Yes
A26: 22 | B26: Part 1 | C26: v1.1.0 | D26: Custom Field | E26: Action__c | F26: Phone_Access_Audit__c | G26: Audit field | I26: Deployed (Sandbox) | J26: 0Afft000000LO8zCAG | K26: Yes
A27: 23 | B27: Part 1 | C27: v1.1.0 | D27: Custom Field | E27: Outcome__c | F27: Phone_Access_Audit__c | G27: Audit field | I27: Deployed (Sandbox) | J27: 0Afft000000LO8zCAG | K27: Yes
A28: 24 | B28: Part 1 | C28: v1.1.0 | D28: Custom Field | E28: User__c | F28: Phone_Access_Audit__c | G28: Audit field | I28: Deployed (Sandbox) | J28: 0Afft000000LO8zCAG | K28: Yes
A29: 25 | B29: Part 1 | C29: v1.1.0 | D29: Custom Field | E29: Record_Id__c | F29: Phone_Access_Audit__c | G29: Audit field | I29: Deployed (Sandbox) | J29: 0Afft000000LO8zCAG | K29: Yes
A30: 26 | B30: Part 1 | C30: v1.1.0 | D30: Custom Field | E30: Object_Name__c | F30: Phone_Access_Audit__c | G30: Audit field | I30: Deployed (Sandbox) | J30: 0Afft000000LO8zCAG | K30: Yes
A31: 27 | B31: Part 1 | C31: v1.1.0 | D31: Custom Field | E31: Field_Key__c | F31: Phone_Access_Audit__c | G31: Audit field | I31: Deployed (Sandbox) | J31: 0Afft000000LO8zCAG | K31: Yes
A32: 28 | B32: Part 1 | C32: v1.1.0 | D32: Custom Field | E32: Masked_Number__c | F32: Phone_Access_Audit__c | G32: Audit field | I32: Deployed (Sandbox) | J32: 0Afft000000LO8zCAG | K32: Yes
A33: 29 | B33: Part 1 | C33: v1.1.0 | D33: Custom Field | E33: Channel__c | F33: Phone_Access_Audit__c | G33: Audit field | I33: Deployed (Sandbox) | J33: 0Afft000000LO8zCAG | K33: Yes
A34: 30 | B34: Part 1 | C34: v1.1.0 | D34: Custom Field | E34: Reason__c | F34: Phone_Access_Audit__c | G34: Audit field | I34: Deployed (Sandbox) | J34: 0Afft000000LO8zCAG | K34: Yes
A35: 31 | B35: Part 1 | C35: v1.1.0 | D35: Custom Field | E35: Message__c | F35: Phone_Access_Audit__c | G35: Audit field | I35: Deployed (Sandbox) | J35: 0Afft000000LO8zCAG | K35: Yes
A36: 32 | B36: Part 1 | C36: v1.1.0 | D36: Custom Field | E36: Event_Time__c | F36: Phone_Access_Audit__c | G36: Audit field | I36: Deployed (Sandbox) | J36: 0Afft000000LO8zCAG | K36: Yes
A37: 33 | B37: Part 1 | C37: v1.1.0 | D37: List View | E37: Phone_Access_Audit__c.All | F37: Phone_Access_Audit__c | G37: All audit rows | I37: Deployed (Sandbox) | J37: 0Afft000000LO8zCAG | K37: Yes
A38: 34 | B38: Part 1 | C38: v1.1.0 | D38: Custom Tab | E38: Phone_Access_Audit__c | G38: Phone Access Audits tab | I38: Deployed (Sandbox) | J38: 0Afft000000LO8zCAG | K38: Yes
A39: 35 | B39: Part 1 | C39: v1.1.0 | D39: Apex Class | E39: PhoneMaskingConfig | G39: Reads masking settings and approved field list | H39: PhoneMaskingConfigTest | I39: Deployed (Sandbox) | J39: 0Afft000000LO8zCAG | K39: Yes | L39: Coverage 98.2%
A40: 36 | B40: Part 1 | C40: v1.1.0 | D40: Apex Class | E40: PhoneMaskUtil | G40: Masks numbers (98XXXXXX21), also inside free text | H40: PhoneMaskUtilTest | I40: Deployed (Sandbox) | J40: 0Afft000000LO8zCAG | K40: Yes | L40: Coverage 100%
A41: 37 | B41: Part 1 | C41: v1.1.0 | D41: Apex Class | E41: MaskedDialService | G41: Secure real-number lookup for dialers; access check; audit | H41: MaskedDialServiceTest | I41: Deployed (Sandbox) | J41: 0Afft000000LO8zCAG | K41: Yes | L41: Coverage 100%
...

Sheet Existing Components
A1: Existing Components that Change
A2: Changed only after approval; original backed up first
A4: # | B4: Part | C4: Version | D4: Metadata Type | E4: API Name | F4: What changes | G4: Why | H4: Approval | I4: Original backup | J4: Status | K4: Needed in Production | L4: Notes
A5: 1 | B5: Part 2 | C5: v1.2.0 | D5: Lightning App (assignment) | E5: Pre_Sales (Gsquare Housing) | F5: One new page-assignment row: Lead, Pre Sales, desktop, POC Masked Rep -> masked page | G5: Show the masked page to POC users only | H5: Approved 2026-10-05 | I5: Commit 1adf63f (snapshot) | J5: Done (Sandbox, App Builder) | K5: Pilot only (manual) | L5: App cannot be deployed by metadata (duplicate Analytics Cloud profile names)
A6: 2 | B6: Part 3 | C6: v1.3.0 | D6: Visualforce Page | E6: mcubeSoftphoneCTIAddOn | F6: In onClickToDial: if the click comes from the masked panel, call the new server method with recordId + fieldKey | G6: MCube receives 98XXXXXX21, which it cannot dial | H6: Approved 2026-10-06 | I6: backup/v1.3.0-pre-change | J6: Deployed (Sandbox) 0Afft000000LY6jCAG | K6: Yes | L6: Normal clicks unchanged
A7: 3 | B7: Part 3 | C7: v1.3.0 | D7: Apex Class | E7: McubeSoftphoneAddOnController | F7: Add new @RemoteAction clickToCallMasked(recordId, fieldKey): resolves via MaskedDialService, then reuses clickToCallRemote | G7: Real number resolved on the server, never in the browser | H7: Approved 2026-10-06 | I7: backup/v1.3.0-pre-change | J7: Deployed (Sandbox) 0Afft000000LY6jCAG | K7: Yes | L7: Existing methods not edited
A8: 4 | B8: Part 3 | C8: v1.3.0 | D8: Aura Component | E8: slashPhone (slashPhoneHelper.js) | F8: In onClickToDial listener: if masked click, runApex MaskedDialServiceCTI.resolveForDial, then continue existing flow | G8: SlashRTC receives 98XXXXXX21 | H8: Approved 2026-10-06 | I8: backup/v1.3.0-pre-change | J8: Deployed (Sandbox) 0Afft000000LY6jCAG | K8: Yes | L8: Number exists briefly inside the SlashRTC softphone (vendor limitation)
A9: 5 | B9: Part 3 | C9: v1.3.0 | D9: Call Center | E9: SlashRTCAdapter | F9: Adapter URL -> sandbox index page | G9: Sandbox adapter points to production | H9: Manual by you (Setup) | I9: backup/v1.3.0-pre-change | J9: Sandbox only - manual | K9: No | L9: Production URL is already correct
A10: 6 | B10: Part 3 | C10: v1.3.0 | D10: User (data) | E10: POC MCube Rep | F10: Set MobilePhone = agent number registered with MCube | G10: MCube rings the agent on User.MobilePhone first | H10: Pending | J10: Sandbox only | K10: No
A11: 7 | B11: Part 4 | C11: v1.4.0 | D11: Aura Component | E11: NewLeadCmp | F11: On form load: if the user cannot see Phone__c, show Phone (entry) + Secondary Phone (entry) inputs instead | G11: Phone__c input disappears for masked users, so they could not create Leads | H11: Approved 2026-10-06 | I11: backup/v1.4.0-pre-change | J11: Deployed (Sandbox) 0Afft000000Lc77CAC | K11: Yes | L11: No change for users who can see Phone__c
A12: 8 | B12: Part 4 | C12: v1.4.0 | D12: Aura Component | E12: NewRefLeadCmp | F12: Same as NewLeadCmp (New Referral Lead quick action) | G12: Same | H12: Approved 2026-10-06 | I12: backup/v1.4.0-pre-change | J12: Deployed (Sandbox) 0Afft000000Lc77CAC | K12: Yes
A13: 9 | B13: Part 4 | C13: v1.4.0 | D13: Apex Trigger | E13: LeadTrigger | F13: One call at the very top (before insert / update): LeadPhoneEntryHandler copies entry fields before the existing formatting and duplicate check | G13: Copy must run before RelatedSourceHandler.checkMobileNumber / duplicateCheck | H13: Approved 2026-10-06 | I13: backup/v1.4.0-pre-change | J13: Deployed (Sandbox) 0Afft000000Lc77CAC | K13: Yes | L13: Existing logic untouched
A14: 10 | B14: Part 4 | C14: v1.4.0 | D14: Apex Class | E14: LeadTriggerHandler / RelatedSourceHandler | F14: No change (existing tests re-run) | G14: Dependency | H14: - | I14: backup/v1.4.0-pre-change | J14: No change | K14: No
A15: 11 | B15: Part 11 | C15: v2.0.0 | D15: Lightning Page | E15: New_Lead_Page | F15: Swap phone fields for entry fields | G15: Fields vanish for masked users | H15: Not requested yet | I15: backup/v1.4.0-pre-change | J15: Planned | K15: Yes
A16: 12 | B16: Part 11 | C16: v2.0.0 | D16: Lightning Page | E16: New_Lead_Page1_sales | F16: Swap phone fields for entry fields | G16: Same | H16: Not requested yet | I16: backup/v1.4.0-pre-change | J16: Planned | K16: Yes
A17: 13 | B17: Part 5 | C17: v1.5.0 | D17: Aura Component | E17: MakeCall | F17: 5a: NO CHANGE needed - shows what readContacts returns and sends it back | G17: Sends full numbers to the browser | H17: - | I17: backup/v1.5.0-part5a-pre-change | J17: No change (5a) | K17: No | L17: Plus its existing test class
A18: 14 | B18: Part 5 | C18: v1.5.0 | D18: Apex Class | E18: MakeCallController | F18: 5a: readContacts returns masked for masked users; callCustomer resolves a masked number on the server | G18: Sends full numbers to the browser | H18: Approved 2026-10-06 | I18: backup/v1.5.0-part5a-pre-change | J18: Deployed (Sandbox) 0Afft000000Lf3NCAS | K18: Yes | L18: Plus its existing test class
A19: 15 | B19: Part 5 | C19: v1.5.0 | D19: Lightning Web Component | E19: utilityCallComponent | F19: 5a: NO CHANGE needed - sends the number back to triggerCall, resolved on the server | G19: Sends full numbers to the browser | H19: - | I19: backup/v1.5.0-part5a-pre-change | J19: No change (5a) | K19: No | L19: Plus its existing test class
A20: 16 | B20: Part 5 | C20: v1.5.0 | D20: Lightning Web Component | E20: offlineCallQuickActionCmp | F20: 5a: NO CHANGE needed (same as utilityCallComponent) | G20: Sends full numbers to the browser | H20: - | I20: backup/v1.5.0-part5a-pre-change | J20: No change (5a) | K20: No | L20: Plus its existing test class
A21: 17 | B21: Part 5 | C21: v1.5.0 | D21: Apex Class | E21: OfflineCallAppAPI | F21: 5a: getLeadPhone / getOppPhone masked for masked users; triggerCall resolves a masked number on the server | G21: Sends full numbers to the browser | H21: Approved 2026-10-06 | I21: backup/v1.5.0-part5a-pre-change | J21: Deployed (Sandbox) 0Afft000000Lf3NCAS | K21: Yes | L21: Plus its existing test class
A22: 18 | B22: Part 5 | C22: v1.5.0 | D22: Aura Component | E22: CallPanel | F22: Postponed: the Aura view form has no onload event. Proposed: replace the Phone line with a new LWC maskedPhoneField | G22: Sends full numbers to the browser | H22: New approach pending approval | I22: backup/v1.5.0-part5a-pre-change | J22: Pending approval | K22: Yes | L22: Plus its existing test class
A23: 19 | B23: Part 5 | C23: v1.5.0 | D23: Aura Component | E23: CallPanel_Outbound | F23: Postponed: the Aura view form has no onload event. Proposed: replace the Phone line with a new LWC maskedPhoneField | G23: Sends full numbers to the browser | H23: New approach pending approval | I23: backup/v1.5.0-part5a-pre-change | J23: Pending approval | K23: Yes | L23: Plus its existing test class
A24: 20 | B24: Part 5 | C24: v1.5.0 | D24: Aura Component | E24: mCubeLightningPage | F24: 5b: NO CHANGE - shows what callRecords returns | G24: Sends full numbers to the browser | H24: - | I24: backup/v1.5.0-part5b-pre-change | J24: No change (5b) | K24: No | L24: Plus its existing test class
A25: 21 | B25: Part 5 | C25: v1.5.0 | D25: Apex Class | E25: LeadHistoryandActivityController | F25: 5b: GetData masks phone history values and call numbers for masked users | G25: Sends full numbers to the browser | H25: Approved 2026-10-06 | I25: backup/v1.5.0-part5b-pre-change | J25: Deployed (Sandbox) 0Afft000000LfszCAC | K25: Yes | L25: Plus its existing test class
A26: 22 | B26: Part 5 | C26: v1.5.0 | D26: Apex Class | E26: mCubeController | F26: 5b: callRecords masked for masked users; log__c Request / Response masked for everyone | G26: Sends full numbers to the browser | H26: Approved 2026-10-06 | I26: backup/v1.5.0-part5b-pre-change | J26: Deployed (Sandbox) 0Afft000000LfszCAC | K26: Yes | L26: Plus its existing test class
A27: 23 | B27: Part 5 | C27: v1.5.0 | D27: Aura Component | E27: LeadMergeCmp | F27: 5c: NO CHANGE - shows what Apex returns | G27: Sends full numbers to the browser | H27: - | I27: backup/v1.5.0-part5c-pre-change | J27: No change (5c) | K27: No | L27: Plus its existing test class
A28: 24 | B28: Part 5 | C28: v1.5.0 | D28: Apex Class | E28: LeadMergeController | F28: Return masked values | G28: Sends full numbers to the browser | H28: Approved 2026-10-07 | I28: backup/v1.5.0-part5c-pre-change | J28: Deployed (Sandbox) 0Afft000000LkRFCA0 | K28: Yes | L28: Plus its existing test class
... A36: 32 | B36: Part 5 | C36: v1.5.0 | D36: Apex Class | E36: LeadMsgConversationController | F36: 5e: mask numbers in conversation message / rawJson / senderName for masked users | G36: Sends full numbers to the browser | H36: Pending approval | I36: backup/v1.5.0-part5e-pre-change | J36: Planned | K36: Yes | L36: Plus its existing test class
A37: 33 | B37: Part 7 | C37: v1.7.0 | D37: Apex Trigger | E37: TaskTrigger | F37: Call FreeTextMaskService on save | G37: Numbers typed in call notes | H37: Not requested yet | I37: Add to baseline first | J37: Planned | K37: Yes
A38: 34 | B38: Part 7 | C38: v1.7.0 | D38: Apex Trigger | E38: CallDetailTrigger | F38: Call FreeTextMaskService on save (free-text fields only) | G38: Numbers typed in call logs | H38: Not requested yet | I38: Add to baseline first | J38: Planned | K38: Yes | L38: Structured number fields untouched
A39: 35 | B39: Part 7 | C39: v1.7.0 | D39: Apex Trigger / Class | E39: Opportunity + feedback object triggers (TBD) | F39: Call FreeTextMaskService on save | G39: Numbers typed in Opportunity / feedback text | H39: Not requested yet | I39: Add to baseline first | J39: Planned | K39: Yes | L39: Exact names confirmed before Part 7
A40: 36 | B40: Part 8 | C40: v1.8.0 | D40: Lightning Web Component | E40: searchComponent | F40: Possibly reuse for Find by number | G40: Global search may stop matching hidden fields | H40: Not requested yet | I40: Baseline v1.0.0 | J40: Conditional | K40: Conditional
A41: 37 | B41: Part 9 | C41: v1.9.0 | D41: Lightning Web Component | E41: cancellationRequest | F41: Fails completely if Opportunity Mobile__c is hidden | G41: Only if Decision 1 = hide Contact / Opportunity numbers | H41: Waiting on Decision 1 | I41: Baseline v1.0.0 | J41: Conditional | K41: Conditional
A42: 38 | B42: Part 9 | C42: v1.9.0 | D42: Lightning Web Component | E42: opportunitySummaryLWC | F42: Masked display | G42: Only if Decision 1 = hide Contact / Opportunity numbers | H42: Waiting on Decision 1 | I42: Baseline v1.0.0 | J42: Conditional | K42: Conditional
A43: 39 | B43: Part 9 | C43: v1.9.0 | D43: Lightning Web Component | E43: registrationTeamFileUpload | F43: Masked display | G43: Only if Decision 1 = hide Contact / Opportunity numbers | H43: Waiting on Decision 1 | I43: Baseline v1.0.0 | J43: Conditional | K43: Conditional
A44: 40 | B44: Part 9 | C44: v1.9.0 | D44: Lightning Web Component | E44: kycAndQuotationTabComponent | F44: Masked co-applicant entry | G44: Only if Decision 1 = hide Contact / Opportunity numbers | H44: Waiting on Decision 1 | I44: Baseline v1.0.0 | J44: Conditional | K44: Conditional
A45: 41 | B45: Part 9 | C45: v1.9.0 | D45: Aura Component | E45: siteVisitFeedbackForm | F45: Masked display | G45: Only if Decision 1 = hide Contact / Opportunity numbers | H45: Waiting on Decision 1 | I45: Baseline v1.0.0 | J45: Conditional | K45: Conditional
A46: 42 | B46: Part 9 | C46: v1.9.0 | D46: Aura Component | E46: createBookingCmp | F46: Masked display | G46: Only if Decision 1 = hide Contact / Opportunity numbers | H46: Waiting on Decision 1 | I46: Baseline v1.0.0 | J46: Conditional | K46: Conditional
A47: 43 | B47: Part 9 | C47: v1.9.0 | D47: Lightning Web Component | E47: showConvertedOppRecord | F47: Masked display | G47: Only if Decision 1 = hide Contact / Opportunity numbers | H47: Waiting on Decision 1 | I47: Baseline v1.0.0 | J47: Conditional | K47: Conditional
A48: 44 | B48: Part 9 | C48: v1.9.0 | D48: Quick Action | E48: Contact.Co_Applicant_1 / 2 / 3, Contact.Update_Contact_Details | F48: Masked entry | G48: Only if Decision 1 = hide Contact / Opportunity numbers | H48: Waiting on Decision 1 | I48: Baseline v1.0.0 | J48: Conditional | K48: Conditional
...

Sheet Prod Deployment List
A1: Production Deployment List (all parts)
A2: Deploy in this order, part by part. Change set test level: Run specified tests (classes in column I). Update "Prod Status" as you go.
A4: Order | B4: Part | C4: Version | D4: Change Set Type | E4: API Name | F4: Parent / Object | G4: New / Existing | H4: Deploy Method | I4: Test class to run | J4: Needed in Production | K4: Prod Status | L4: Notes
A5: 1 | B5: Part 1 | C5: v1.1.0 | D5: Custom Metadata Type | E5: Masked_Phone_Field__mdt | G5: New | H5: Change set | J5: Yes | K5: Not deployed
A6: 2 | B6: Part 1 | C6: v1.1.0 | D6: Custom Metadata Type | E6: Phone_Masking_Setting__mdt | G6: New | H6: Change set | J6: Yes | K6: Not deployed
A7: 3 | B7: Part 1 | C7: v1.1.0 | D7: Custom Object | E7: Phone_Access_Audit__c | G7: New | H7: Change set | J7: Yes | K7: Not deployed
A8: 4 | B8: Part 1 | C8: v1.1.0 | D8: Custom Field | E8: Action__c | F8: Phone_Access_Audit__c | G8: New | H8: Change set | J8: Yes | K8: Not deployed
A9: 5 | B9: Part 1 | C9: v1.1.0 | D9: Custom Field | E9: Active__c | F9: Masked_Phone_Field__mdt | G9: New | H9: Change set | J9: Yes | K9: Not deployed
A10: 6 | B10: Part 1 | C10: v1.1.0 | D10: Custom Field | E10: Allow_Dial__c | F10: Masked_Phone_Field__mdt | G10: New | H10: Change set | J10: Yes | K10: Not deployed
A11: 7 | B11: Part 1 | C11: v1.1.0 | D11: Custom Field | E11: Allow_Reveal__c | F11: Masked_Phone_Field__mdt | G11: New | H11: Change set | J11: Yes | K11: Not deployed
A12: 8 | B12: Part 1 | C12: v1.1.0 | D12: Custom Field | E12: Audit_Enabled__c | F12: Phone_Masking_Setting__mdt | G12: New | H12: Change set | J12: Yes | K12: Not deployed
A13: 9 | B13: Part 1 | C13: v1.1.0 | D13: Custom Field | E13: Audit_Retention_Days__c | F13: Phone_Masking_Setting__mdt | G13: New | H13: Change set | J13: Yes | K13: Not deployed
A14: 10 | B14: Part 1 | C14: v1.1.0 | D14: Custom Field | E14: Channel__c | F14: Phone_Access_Audit__c | G14: New | H14: Change set | J14: Yes | K14: Not deployed
A15: 11 | B15: Part 1 | C15: v1.1.0 | D15: Custom Field | E15: Country_Code_To_Strip__c | F15: Phone_Masking_Setting__mdt | G15: New | H15: Change set | J15: Yes | K15: Not deployed
A16: 12 | B16: Part 1 | C16: v1.1.0 | D16: Custom Field | E16: Display_Label__c | F16: Masked_Phone_Field__mdt | G16: New | H16: Change set | J16: Yes | K16: Not deployed
A17: 13 | B17: Part 1 | C17: v1.1.0 | D17: Custom Field | E17: Event_Time__c | F17: Phone_Access_Audit__c | G17: New | H17: Change set | J17: Yes | K17: Not deployed
A18: 14 | B18: Part 1 | C18: v1.1.0 | D18: Custom Field | E18: Field_API_Name__c | F18: Masked_Phone_Field__mdt | G18: New | H18: Change set | J18: Yes | K18: Not deployed
A19: 15 | B19: Part 1 | C19: v1.1.0 | D19: Custom Field | E19: Field_Key__c | F19: Phone_Access_Audit__c | G19: New | H19: Change set | J19: Yes | K19: Not deployed
... A37: 33 | B37: Part 1 | C37: v1.1.0 | D37: List View | E37: Phone_Access_Audit__c.All | F37: Phone_Access_Audit__c | G37: New | H37: Change set | J37: Yes | K37: Not deployed
A38: 34 | B38: Part 1 | C38: v1.1.0 | D38: Custom Tab | E38: Phone_Access_Audit__c | G38: New | H38: Change set | J38: Yes | K38: Not deployed
A39: 35 | B39: Part 1 | C39: v1.1.0 | D39: Apex Class | E39: MaskedDialService | G39: New | H39: Change set | I39: MaskedDialServiceTest | J39: Yes | K39: Not deployed | L39: Coverage 100%
A40: 36 | B40: Part 1 | C40: v1.1.0 | D40: Apex Class | E40: MaskedDialServiceCTI | G40: New | H40: Change set | I40: MaskedDialServiceCTITest | J40: Yes | K40: Not deployed | L40: Coverage 93.5%
A41: 37 | B41: Part 1 | C41: v1.1.0 | D41: Apex Class | E41: PhoneMaskingConfig | G41: New | H41: Change set | I41: PhoneMaskingConfigTest | J41: Yes | K41: Not deployed | L41: Coverage 98.2%
A42: 38 | B42: Part 1 | C42: v1.1.0 | D42: Apex Class | E42: PhoneMaskUtil | G42: New | H42: Change set | I42: PhoneMaskUtilTest | J42: Yes | K42: Not deployed | L42: Coverage 100%
A43: 39 | B43: Part 1 | C43: v1.1.0 | D43: Apex Class (test) | E43: MaskedDialServiceCTITest | G43: New | H43: Change set | J43: Yes | K43: Not deployed
A44: 40 | B44: Part 1 | C44: v1.1.0 | D44: Apex Class (test) | E44: MaskedDialServiceTest | G44: New | H44: Change set | J44: Yes | K44: Not deployed
A45: 41 | B45: Part 1 | C45: v1.1.0 | D45: Apex Class (test) | E45: PhoneMaskingConfigTest | G45: New | H45: Change set | J45: Yes | K45: Not deployed
A46: 42 | B46: Part 1 | C46: v1.1.0 | D46: Apex Class (test) | E46: PhoneMaskUtilTest | G46: New | H46: Change set | J46: Yes | K46: Not deployed
A47: 43 | B47: Part 1 | C47: v1.1.0 | D47: Apex Class (test) | E47: PhoneTestDataFactory | G47: New | H47: Change set | J47: Yes | K47: Not deployed
A48: 44 | B48: Part 1 | C48: v1.1.0 | D48: Permission Set | E48: Phone_Access_Audit_Viewer | G48: New | H48: Change set | J48: Yes | K48: Not deployed | L48: Assign to admins after deploy
A49: 45 | B49: Part 2 | C49: v1.2.0 | D49: Apex Class | E49: MaskedPhonePanelController | G49: New | H49: Change set | I49: MaskedPhonePanelControllerTest | J49: Yes | K49: Not deployed | L49: Coverage 100%
A50: 46 | B50: Part 2 | C50: v1.2.0 | D50: Apex Class (test) | E50: MaskedPhonePanelControllerTest | G50: New | H50: Change set | J50: Yes | K50: Not deployed
A51: 47 | B51: Part 2 | C51: v1.2.0 | D51: Lightning Web Component | E51: maskedPhonePanel | G51: New | H51: Change set | I51: Jest (2 files, not deployed) | J51: Yes | K51: Not deployed | L51: Jest needs Node.js locally
A52: 48 | B52: Part 2 | C52: v1.2.0 | D52: Lightning Page | E52: Sales_Lead_Record_Page_Masked_POC | G52: New | H52: Change set | J52: Pilot only | K52: Not deployed | L52: Deleted after go-live (Part 11)
A53: 49 | B53: Part 2 | C53: v1.2.0 | D53: Profile | E53: POC Masked Rep | G53: New | H53: Change set | J53: Pilot only (decide) | K53: Not deployed | L53: Cloned manually in Setup; overlay deployed
A54: 50 | B54: Part 2 | C54: v1.2.0 | D54: Lightning App (assignment) | E54: Pre_Sales (Gsquare Housing) | G54: Existing (change) | H54: Manual / Change set | J54: Pilot only (manual) | K54: Not deployed | L54: One new page-assignment row: Lead, Pre Sales, desktop, POC Masked Rep -> masked page
A55: 51 | B55: Part 3 | C55: v1.3.0 | D55: Lightning Message Channel | E55: MaskedDialRequest__c | G55: New | H55: Change set | J55: Conditional | K55: Not deployed | L55: Only if POC shows masked click-to-dial fails
A56: 52 | B56: Part 3 | C56: v1.3.0 | D56: Apex Class (update of new) | E56: MaskedDialService | G56: New | H56: Change set | I56: MaskedDialServiceTest | J56: Yes | K56: Not deployed | L56: Part 1 component updated
A57: 53 | B57: Part 3 | C57: v1.3.0 | D57: Apex Class (update of new) | E57: MaskedDialServiceCTI | G57: New | H57: Change set | I57: MaskedDialServiceCTITest | J57: Yes | K57: Not deployed | L57: Part 1 component updated
A58: 54 | B58: Part 3 | C58: v1.3.0 | D58: Apex Class | E58: McubeSoftphoneAddOnController | G58: Existing (change) | H58: Change set | J58: Yes | K58: Not deployed | L58: Add new @RemoteAction clickToCallMasked(recordId, fieldKey): resolves via MaskedDialService, then reuses clickToCallRemote
...

Sheet Manual Steps
A1: Manual Steps (cannot be deployed)
A2: Do these in Setup at the right point of each part
A4: Step | B4: Part | C4: What to do | D4: Where | E4: Sandbox status | F4: Needed in Production
A5: M1 | B5: Part 1 | C5: Assign permission set Phone Access Audit Viewer to admins who review audits | D5: Setup > Permission Sets | E5: Not done | F5: Yes
A6: M2 | B6: Part 2 | C6: Clone profile Presales outbound -> POC Masked Rep | D6: Setup > Profiles > Clone | E6: Done | F6: Pilot only (decide)
A7: M3 | B7: Part 2 | C7: Activate Sales_Lead_Record_Page_Masked_POC for Gsquare Housing / Desktop / Pre Sales / POC Masked Rep | D7: Lightning App Builder > Activation | E7: Done | F7: Pilot only
A8: M4 | B8: Part 2 | C8: Create test users POC MCube Rep, POC SlashRTC Rep | D8: Setup > Users | E8: Done | F8: No
A9: M5 | B9: Part 2 | C9: Create Pre Sales test Leads owned by each test user (tester or dummy numbers) | D9: Leads | E9: Not done | F9: No
A10: M6 | B10: Part 3 | C10: Set POC MCube Rep MobilePhone = agent number registered with MCube | D10: Setup > Users | E10: Not done | F10: No
A11: M7 | B11: Part 3 | C11: SlashRTC agent exists for POC SlashRTC Rep email (tptUniqueId = user email); sandbox origin allowed by SlashRTC | D11: SlashRTC admin / vendor | E11: Not done | F11: No
A12: M8 | B12: Part 3 | C12: SlashRTC call center CTI Adapter URL -> /apex/index (sandbox only, done manually by you) | D12: Setup > Call Centers > SlashRTC Call Center Adapter > Edit | E12: Manual - pending | F12: No
A13: M9 | B13: Part 6 | C13: Schedule PhoneAuditPurgeBatch nightly | D13: Setup > Apex Classes > Schedule Apex | E13: Not started | F13: Yes
A14: M10 | B14: Part 6 | C14: Assign Phone_Number_Reveal to TLs, Heads, Admins | D14: Setup > Permission Sets | E14: Not started | F14: Yes
A15: M11 | B15: Part 11 | C15: Assign Phone_Number_Full_Access to integration users (MCube, Yotel, Zetta, website/portal, SlashRTC log user) | D15: Setup > Permission Sets | E15: Not started | F15: Yes
... A17: M13 | B17: Part 13 | C17: Production: Validate change set with Run specified tests, then Quick Deploy | D17: Setup > Inbound Change Sets | E17: Not started | F17: Yes

Sheet Test Classes
A1: Test Classes and Coverage
A2: Target above 85% per class, never SeeAllData
A4: Test class | B4: Covers | C4: Part | D4: Tests | E4: Coverage (sandbox) | F4: Status
A5: PhoneMaskUtilTest | B5: PhoneMaskUtil | C5: Part 1 | D5: 12 | E5: 100% | F5: Deployed (Sandbox)
A6: PhoneMaskingConfigTest | B6: PhoneMaskingConfig | C6: Part 1 | D6: 6 | E6: 98.2% | F6: Deployed (Sandbox)
A7: MaskedDialServiceTest | B7: MaskedDialService | C7: Part 1 | D7: 18 | E7: 100% | F7: Deployed (Sandbox)
A8: MaskedDialServiceCTITest | B8: MaskedDialServiceCTI | C8: Part 1 | D8: 6 | E8: 93.5% | F8: Deployed (Sandbox)
A9: PhoneTestDataFactory | B9: (test data utility) | C9: Part 1 | D9: - | E9: - | F9: Deployed (Sandbox)
A10: MaskedPhonePanelControllerTest | B10: MaskedPhonePanelController | C10: Part 2 | D10: 11 | E10: 100% | F10: Deployed (Sandbox)
A11: McubeMaskedClickToCallTest + McubeSoftphoneAddOnControllerTest | B11: McubeSoftphoneAddOnController | C11: Part 3 | D11: - | E11: 87.9% | F11: Deployed (Sandbox)
A12: MaskedDialServiceTest (v1.3.0, +5) | B12: MaskedDialService | C12: Part 3 | D12: 23 | E12: 100% | F12: Deployed (Sandbox)
A13: MaskedDialServiceCTITest (v1.3.0, +3) | B13: MaskedDialServiceCTI | C13: Part 3 | D13: 9 | E13: 94.4% | F13: Deployed (Sandbox)
A14: LeadPhoneEntryHandlerTest (+ LeadTriggerTest, LeadTriggerHandlerTest) | B14: LeadPhoneEntryHandler, LeadTrigger | C14: Part 4 | D14: 20 | E14: Handler 100% Â· LeadTrigger 80.1% | F14: Deployed (Sandbox)
A15: (existing test classes of Part 5 components) | B15: Part 5 changed classes | C15: Part 5 | E15: keep >= current | F15: Planned
A16: PhoneRevealServiceTest | B16: PhoneRevealService | C16: Part 6 | E16: target > 85% | F16: Planned
A17: PhoneAuditPurgeBatchTest | B17: PhoneAuditPurgeBatch | C17: Part 6 | E17: target > 85% | F17: Planned
A18: FreeTextMaskServiceTest | B18: FreeTextMaskService, FeedItemPhoneMaskTrigger | C18: Part 7 | E18: target > 85% | F18: Planned
A19: FindByNumberControllerTest | B19: FindByNumberController | C19: Part 8 | E19: target > 85% | F19: Conditional

Sheet Backups
A1: Backups of Original Code
A2: Taken before any existing component changes
A4: Backup | B4: Contents | C4: Location | D4: Retrieved | E4: Git commit | F4: Status
A5: Baseline v1.0.0 | B5: 528 files: 44 Apex, LeadTrigger, 12 Aura, 11 LWC, 21 VF, 4 Lightning pages, 4 quick actions, 3 flows, 3 call centers, 38 phone fields, 167 profiles, 47 permission sets | C5: force-app (git tag v1.0.0) | D5: 2026-10-03 | E5: 9a87598 | F5: Backed up
A6: Pre_Sales app snapshot | B6: Gsquare Housing app before the POC row | C6: force-app/main/default/applications (commit 1adf63f) | D6: 2026-10-05 | E6: 1adf63f | F6: Backed up
A7: Part 3 pre-change backup | B7: mcubeSoftphoneCTIAddOn, McubeSoftphoneAddOnController (+Test), index, slashPhone, slashPhoneApp, leadOp (+Test), 3 call centers | C7: backup/v1.3.0-pre-change (with SHA256SUMS) | D7: 2026-10-06 | E7: f2c7e4f | F7: Backed up
A8: Part 4 pre-change backup | B8: LeadTrigger, NewLeadCmp, NewRefLeadCmp, RelatedSourceHandler, LeadTriggerHandler (+tests), New_Lead_Page, New_Lead_Page1_sales (changed since baseline: +8 lines tab display), Lead.New_Referral_Lead | C8: backup/v1.4.0-pre-change (with SHA256SUMS) | D8: 2026-10-06 | E8: 9b32c8c | F8: Backed up
A9: Part 5a pre-change backup | B9: MakeCall + MakeCallController (+Test), OfflineCallAppAPI (+Test), utilityCallComponent, offlineCallQuickActionCmp, CallPanel, CallPanel_Outbound - identical to baseline | C9: backup/v1.5.0-part5a-pre-change (with SHA256SUMS) | D9: 2026-10-06 | E9: 3c0330b | F9: Backed up
A10: Before Part 7 | B10: TaskTrigger, CallDetailTrigger and handlers (not in baseline) | C10: backup/v1.7.0-pre-change | F10: Planned
A11: Before Part 11 | B11: All rep profiles, Lead_Record_Page3 | C11: backup/v2.0.0-pre-change | F11: Planned

Sheet Part 3 Plan
A1: Part 3 (v1.3.0) - Dialer adapters, POC
A2: Explained before implementation; nothing changed yet
A4: New / Existing | B4: Type | C4: Component | D4: Change | E4: Effect for users | F4: Risk
A5: New | B5: Apex test class | C5: McubeMaskedClickToCallTest | D5: Tests the new MCube method: masked click resolves the real number on the server and places the call (MCube callout mocked); denied / no-access / blank cases | E5: None (tests only) | F5: None
A6: Existing | B6: Apex Class | C6: McubeSoftphoneAddOnController | D6: ADD one method clickToCallMasked(recordId, fieldKey): MaskedDialService.resolveOne -> existing clickToCallRemote(recordId, realNumber). Existing methods not edited. | E6: POC MCube user can call from the masked panel; the real number never reaches the browser | F6: Low: additive only
A7: Existing | B7: Visualforce Page | C7: mcubeSoftphoneCTIAddOn | D7: In the onClickToDial listener: IF the click carries fieldKey (masked panel) -> call clickToCallMasked; ELSE existing code unchanged | E7: Normal Phone__c clicks behave exactly as today | F7: Low: one branch
A8: Existing | B8: Aura Component | C8: slashPhone (slashPhoneHelper.js) | D8: In the onClickToDial listener: IF masked click -> runApex MaskedDialServiceCTI.resolveForDial(recordId, fieldKey), replace the number, then run the existing flow (leadOp lookup + postMessage to SlashRTC iframe) | E8: POC SlashRTC user can call from the panel. Real number exists briefly inside the SlashRTC softphone (vendor limitation) | F8: Medium: SlashRTC must accept sandbox origin
A9: Existing (sandbox only) | B9: Call Center | C9: SlashRTCAdapter | D9: Adapter URL -> sandbox index page | E9: SlashRTC softphone in sandbox loads the sandbox page | F9: None in production
A10: New (update) | B10: Profile | C10: POC Masked Rep | D10: Add class access MaskedDialServiceCTI | E10: SlashRTC runApex allowed for POC users | F10: None
A11: New (update) | B11: Lightning Page | C11: Sales_Lead_Record_Page_Masked_POC | D11: Panel property Enable click-to-dial = true | E11: Masked numbers become clickable for POC users | F11: None for other users
A12: Data | B12: User | C12: POC MCube Rep | D12: MobilePhone = agent number registered with MCube | E12: MCube can ring the agent | F12: None
A13: No change | B13: Apex Class | C13: leadOp | D13: None: returns record Ids only (earlier plan corrected) | E13: - | F13: -
A14: No change | B14: Visualforce Page | C14: index | D14: None: screen pop uses recordId | E14: - | F14: -
A15: Not in POC | B15: Managed package | C15: 360CTI (186 users) | D15: Vendor change required | E15: - | F15: Vendor dependency

Sheet Release Bundle
A1: Production Release Bundle - built components (Parts 1-5d)
A2: Every file in release/prod, converted from the sandbox-tested source. Checksums in release/prod/SHA256SUMS. Rebuild: bash scripts/release/build-prod-release.sh
A4: Deploy order | B4: Bundle folder | C4: Part | D4: Version | E4: Metadata Type | F4: Component | G4: File path | H4: SHA-256 (first 12) | I4: For | J4: Tested in sandbox | K4: Prod Status
A5: 1 | B5: part1-foundations | C5: Part 1 | D5: v1.1.0 | E5: Apex Class | F5: MaskedDialService | G5: release/prod/part1-foundations/classes/MaskedDialService.cls | H5: a8c2c5dc228b | I5: Production - everyone | J5: Deployed (Sandbox) 0Afft000000LO8zCAG | K5: Not deployed
A6: 1 | B6: part1-foundations | C6: Part 1 | D6: v1.1.0 | E6: Apex Class | F6: MaskedDialService | G6: release/prod/part1-foundations/classes/MaskedDialService.cls-meta.xml | H6: 87b91a7450c6 | I6: Production - everyone | J6: Deployed (Sandbox) 0Afft000000LO8zCAG | K6: Not deployed
A7: 1 | B7: part1-foundations | C7: Part 1 | D7: v1.1.0 | E7: Apex Class | F7: MaskedDialServiceCTI | G7: release/prod/part1-foundations/classes/MaskedDialServiceCTI.cls | H7: c5bedd971363 | I7: Production - everyone | J7: Deployed (Sandbox) 0Afft000000LO8zCAG | K7: Not deployed
A8: 1 | B8: part1-foundations | C8: Part 1 | D8: v1.1.0 | E8: Apex Class | F8: MaskedDialServiceCTI | G8: release/prod/part1-foundations/classes/MaskedDialServiceCTI.cls-meta.xml | H8: 87b91a7450c6 | I8: Production - everyone | J8: Deployed (Sandbox) 0Afft000000LO8zCAG | K8: Not deployed
A9: 1 | B9: part1-foundations | C9: Part 1 | D9: v1.1.0 | E9: Apex Class | F9: PhoneMaskingConfig | G9: release/prod/part1-foundations/classes/PhoneMaskingConfig.cls | H9: 35b3fcb96581 | I9: Production - everyone | J9: Deployed (Sandbox) 0Afft000000LO8zCAG | K9: Not deployed
A10: 1 | B10: part1-foundations | C10: Part 1 | D10: v1.1.0 | E10: Apex Class | F10: PhoneMaskingConfig | G10: release/prod/part1-foundations/classes/PhoneMaskingConfig.cls-meta.xml | H10: 87b91a7450c6 | I10: Production - everyone | J10: Deployed (Sandbox) 0Afft000000LO8zCAG | K10: Not deployed
A11: 1 | B11: part1-foundations | C11: Part 1 | D11: v1.1.0 | E11: Apex Class | F11: PhoneMaskUtil | G11: release/prod/part1-foundations/classes/PhoneMaskUtil.cls | H11: ea923f1f15bc | I11: Production - everyone | J11: Deployed (Sandbox) 0Afft000000LO8zCAG | K11: Not deployed
A12: 1 | B12: part1-foundations | C12: Part 1 | D12: v1.1.0 | E12: Apex Class | F12: PhoneMaskUtil | G12: release/prod/part1-foundations/classes/PhoneMaskUtil.cls-meta.xml | H12: 87b91a7450c6 | I12: Production - everyone | J12: Deployed (Sandbox) 0Afft000000LO8zCAG | K12: Not deployed
A13: 1 | B13: part1-foundations | C13: Part 1 | D13: v1.1.0 | E13: Apex Class (test) | F13: MaskedDialServiceCTITest | G13: release/prod/part1-foundations/classes/MaskedDialServiceCTITest.cls | H13: 2de826792691 | I13: Production - everyone | J13: Deployed (Sandbox) 0Afft000000LO8zCAG | K13: Not deployed
A14: 1 | B14: part1-foundations | C14: Part 1 | D14: v1.1.0 | E14: Apex Class (test) | F14: MaskedDialServiceCTITest | G14: release/prod/part1-foundations/classes/MaskedDialServiceCTITest.cls-meta.xml | H14: 87b91a7450c6 | I14: Production - everyone | J14: Deployed (Sandbox) 0Afft000000LO8zCAG | K14: Not deployed
A15: 1 | B15: part1-foundations | C15: Part 1 | D15: v1.1.0 | E15: Apex Class (test) | F15: MaskedDialServiceTest | G15: release/prod/part1-foundations/classes/MaskedDialServiceTest.cls | H15: be47f9305354 | I15: Production - everyone | J15: Deployed (Sandbox) 0Afft000000LO8zCAG | K15: Not deployed
A16: 1 | B16: part1-foundations | C16: Part 1 | D16: v1.1.0 | E16: Apex Class (test) | F16: MaskedDialServiceTest | G16: release/prod/part1-foundations/classes/MaskedDialServiceTest.cls-meta.xml | H16: 87b91a7450c6 | I16: Production - everyone | J16: Deployed (Sandbox) 0Afft000000LO8zCAG | K16: Not deployed
... A52: 3 | B52: part3-dialers | C52: Part 3 | D52: v1.3.0 | E52: Visualforce Page | F52: mcubeSoftphoneCTIAddOn | G52: release/prod/part3-dialers/pages/mcubeSoftphoneCTIAddOn.page-meta.xml | H52: b4c9950e6bc4 | I52: Production - everyone | J52: Deployed (Sandbox) 0Afft000000LY6jCAG | K52: Not deployed
A53: 4 | B53: part4-lead-entry | C53: Part 4 | D53: v1.4.0 | F53: LeadTrigger.trigger | G53: release/prod/part4-lead-entry/triggers/LeadTrigger.trigger | H53: d76c4f8924ec | I53: Production - everyone | J53: Deployed (Sandbox) 0Afft000000Lc77CAC | K53: Not deployed
A54: 4 | B54: part4-lead-entry | C54: Part 4 | D54: v1.4.0 | F54: LeadTrigger.trigger | G54: release/prod/part4-lead-entry/triggers/LeadTrigger.trigger-meta.xml | H54: 7a7f3d2d53ba | I54: Production - everyone | J54: Deployed (Sandbox) 0Afft000000Lc77CAC | K54: Not deployed
A55: 4 | B55: part4-lead-entry | C55: Part 4 | D55: v1.4.0 | E55: Apex Class | F55: LeadPhoneEntryHandler | G55: release/prod/part4-lead-entry/classes/LeadPhoneEntryHandler.cls | H55: 44394fa359a3 | I55: Production - everyone | J55: Deployed (Sandbox) 0Afft000000Lc77CAC | K55: Not deployed
A56: 4 | B56: part4-lead-entry | C56: Part 4 | D56: v1.4.0 | E56: Apex Class | F56: LeadPhoneEntryHandler | G56: release/prod/part4-lead-entry/classes/LeadPhoneEntryHandler.cls-meta.xml | H56: 87b91a7450c6 | I56: Production - everyone | J56: Deployed (Sandbox) 0Afft000000Lc77CAC | K56: Not deployed
A57: 4 | B57: part4-lead-entry | C57: Part 4 | D57: v1.4.0 | E57: Apex Class (test) | F57: LeadPhoneEntryHandlerTest | G57: release/prod/part4-lead-entry/classes/LeadPhoneEntryHandlerTest.cls | H57: ff4bcdf806b0 | I57: Production - everyone | J57: Deployed (Sandbox) 0Afft000000Lc77CAC | K57: Not deployed
A58: 4 | B58: part4-lead-entry | C58: Part 4 | D58: v1.4.0 | E58: Apex Class (test) | F58: LeadPhoneEntryHandlerTest | G58: release/prod/part4-lead-entry/classes/LeadPhoneEntryHandlerTest.cls-meta.xml | H58: 87b91a7450c6 | I58: Production - everyone | J58: Deployed (Sandbox) 0Afft000000Lc77CAC | K58: Not deployed
A59: 4 | B59: part4-lead-entry | C59: Part 4 | D59: v1.4.0 | E59: Aura Component | F59: NewLeadCmp | G59: release/prod/part4-lead-entry/aura/NewLeadCmp/NewLeadCmp.auradoc | H59: 60705e943572 | I59: Production - everyone | J59: Deployed (Sandbox) 0Afft000000Lc77CAC | K59: Not deployed
A60: 4 | B60: part4-lead-entry | C60: Part 4 | D60: v1.4.0 | E60: Aura Component | F60: NewLeadCmp | G60: release/prod/part4-lead-entry/aura/NewLeadCmp/NewLeadCmp.cmp | H60: a883464b3486 | I60: Production - everyone | J60: Deployed (Sandbox) 0Afft000000Lc77CAC | K60: Not deployed
A61: 4 | B61: part4-lead-entry | C61: Part 4 | D61: v1.4.0 | E61: Aura Component | F61: NewLeadCmp | G61: release/prod/part4-lead-entry/aura/NewLeadCmp/NewLeadCmp.cmp-meta.xml | H61: 26bafa2e57d5 | I61: Production - everyone | J61: Deployed (Sandbox) 0Afft000000Lc77CAC | K61: Not deployed
A62: 4 | B62: part4-lead-entry | C62: Part 4 | D62: v1.4.0 | E62: Aura Component | F62: NewLeadCmp | G62: release/prod/part4-lead-entry/aura/NewLeadCmp/NewLeadCmp.css | H62: e0afee0398c4 | I62: Production - everyone | J62: Deployed (Sandbox) 0Afft000000Lc77CAC | K62: Not deployed
A63: 4 | B63: part4-lead-entry | C63: Part 4 | D63: v1.4.0 | E63: Aura Component | F63: NewLeadCmp | G63: release/prod/part4-lead-entry/aura/NewLeadCmp/NewLeadCmp.design | H63: 5ff4b67b38f3 | I63: Production - everyone | J63: Deployed (Sandbox) 0Afft000000Lc77CAC | K63: Not deployed
A64: 4 | B64: part4-lead-entry | C64: Part 4 | D64: v1.4.0 | E64: Aura Component | F64: NewLeadCmp | G64: release/prod/part4-lead-entry/aura/NewLeadCmp/NewLeadCmpController.js | H64: 441aea094a35 | I64: Production - everyone | J64: Deployed (Sandbox) 0Afft000000Lc77CAC | K64: Not deployed
A65: 4 | B65: part4-lead-entry | C65: Part 4 | D65: v1.4.0 | E65: Aura Component | F65: NewLeadCmp | G65: release/prod/part4-lead-entry/aura/NewLeadCmp/NewLeadCmpHelper.js | H65: f78896d8f5bd | I65: Production - everyone | J65: Deployed (Sandbox) 0Afft000000Lc77CAC | K65: Not deployed
A66: 4 | B66: part4-lead-entry | C66: Part 4 | D66: v1.4.0 | E66: Aura Component | F66: NewLeadCmp | G66: release/prod/part4-lead-entry/aura/NewLeadCmp/NewLeadCmpRenderer.js | H66: 38731048a539 | I66: Production - everyone | J66: Deployed (Sandbox) 0Afft000000Lc77CAC | K66: Not deployed
... A115: 9 | B115: part2-pilot | C115: Part 2 | D115: v1.2.0 | E115: Profile | F115: POC Masked Rep | G115: release/prod/part2-pilot/profiles/POC Masked Rep.profile | H115: df1ecd8c7bec | I115: Production pilot only (clone POC profile first) | J115: Deployed (Sandbox) 0Afft000000LRq1CAG / 0Afft000000LRzhCAG | K115: Not deployed

Sheet Release Steps
A1: Production Deploy Steps (Parts 1-5d)
A2: Validate first, then quick deploy. Replace <prod> with the production org alias.
A4: Step | B4: Bundle | C4: What | D4: Command / Where | E4: Prod Status
A5: 1 | B5: part1-foundations | C5: Validate in production, then quick deploy | D5: sf project deploy validate --metadata-dir release/prod/part1-foundations --test-level RunSpecifiedTests --tests PhoneMaskingConfigTest --tests PhoneMaskUtilTest --tests MaskedDialServiceTest --tests MaskedDialServiceCTITest | E5: --target-org <prod> then sf project deploy quick --job-id <id> --target-org <prod>
A6: 2 | B6: part2-panel | C6: Validate in production, then quick deploy | D6: sf project deploy validate --metadata-dir release/prod/part2-panel --test-level RunSpecifiedTests --tests MaskedPhonePanelControllerTest | E6: --target-org <prod> then sf project deploy quick --job-id <id> --target-org <prod>
A7: 3 | B7: part2-pilot | C7: Pilot only: clone Presales outbound -> POC Masked Rep in Setup, then deploy | D7: sf project deploy start --metadata-dir release/prod/part2-pilot --test-level NoTestRun | E7: --target-org <prod>
A8: 3b | B8: part3-dialers | C8: Validate in production, then quick deploy | D8: sf project deploy validate --metadata-dir release/prod/part3-dialers --test-level RunSpecifiedTests --tests McubeMaskedClickToCallTest --tests McubeSoftphoneAddOnControllerTest | E8: --target-org <prod> then sf project deploy quick --job-id <id> --target-org <prod>
A9: 3c | B9: part4-lead-entry | C9: Validate in production, then quick deploy | D9: sf project deploy validate --metadata-dir release/prod/part4-lead-entry --test-level RunSpecifiedTests --tests LeadPhoneEntryHandlerTest --tests LeadTriggerTest --tests LeadTriggerHandlerTest | E9: --target-org <prod> then sf project deploy quick --job-id <id> --target-org <prod>
A10: 3d | B10: part5a-calling | C10: Validate in production, then quick deploy | D10: sf project deploy validate --metadata-dir release/prod/part5a-calling --test-level RunSpecifiedTests --tests PhoneDisplayServiceTest --tests PhoneMaskingCallScreensTest --tests MakeCallControllerTest --tests OfflineCallAppAPITest --tests MaskedDialServiceTest | E10: --target-org <prod> then sf project deploy quick --job-id <id> --target-org <prod>
A11: 3e | B11: part5b-history | C11: Validate in production, then quick deploy | D11: sf project deploy validate --metadata-dir release/prod/part5b-history --test-level RunSpecifiedTests --tests PhoneMaskingHistoryTest --tests PhoneDisplayServiceTest --tests mCubeController_Test --tests mCubeControllerTestExtended --tests LeadHistoryandActivityControllerTest | E11: --target-org <prod> then sf project deploy quick --job-id <id> --target-org <prod>
A12: 3f | B12: part5c-lead-tools | C12: Validate in production, then quick deploy | D12: sf project deploy validate --metadata-dir release/prod/part5c-lead-tools --test-level RunSpecifiedTests --tests PhoneMaskingLeadToolsTest --tests PhoneDisplayServiceTest --tests LeadMergeControllerTest (not updateContactDetailsTest - fails before 5c, D3) | E12: --target-org <prod> then sf project deploy quick --job-id <id> --target-org <prod>
A13: 3g | B13: part5d-push | C13: Validate in production, then quick deploy | D13: sf project deploy validate --metadata-dir release/prod/part5d-push --test-level RunSpecifiedTests --tests PhoneMaskingPushTest --tests LeadBulkPushControllerTest --tests LeadYotelBulkPushControllerTest | E13: --target-org <prod> then sf project deploy quick --job-id <id> --target-org <prod>
A14: 4 | B14: (manual) | C14: Assign Phone Access Audit Viewer to admins | D14: Setup > Permission Sets | E14: Not deployed
A15: 5 | B15: (manual, pilot) | C15: Activate masked POC page: Gsquare Housing / Desktop / Pre Sales / POC Masked Rep | D15: Lightning App Builder > Activation | E15: Not deployed
A16: 6 | B16: (check) | C16: Run scripts/apex/v1.1.0-1 and -2 (read-only) | D16: Developer Console > Execute Anonymous | E16: Not deployed

Sheet Part 4 Plan
A1: Part 4 (v1.4.0) - Lead creation with hidden numbers
A2: Explained before implementation; originals backed up in backup/v1.4.0-pre-change
A4: New / Existing | B4: Type | C4: Component | D4: Change | E4: Effect for users | F4: Risk
A5: New | B5: Custom Field (Phone) | C5: Lead.Phone_Entry__c | D5: Label "Phone". Reps type the primary number here when creating a Lead. Always empty after save. | E5: Masked reps can create Leads | F5: None
A6: New | B6: Custom Field (Phone) | C6: Lead.Secondary_Phone_Entry__c | D6: Label "Secondary Phone". Add / change the secondary number. Always empty after save. | E6: Masked reps can add or change the secondary number | F6: None
A7: New | B7: Apex Class | C7: LeadPhoneEntryHandler | D7: Before insert / update: copies entry -> Phone__c / Secondary_Phone__c and clears the entry fields. Primary is locked once set (error if an entry value tries to change it). Bulk-safe, no SOQL / DML. | E7: Numbers are saved in the real (hidden) fields exactly as today | F7: Low
A8: New | B8: Apex Class (test) | C8: LeadPhoneEntryHandlerTest | D8: Insert, update, lock, secondary change, blank, 200-record bulk, runAs masked user; > 85%, no SeeAllData | E8: - | F8: -
A9: Existing | B9: Apex Trigger | C9: LeadTrigger | D9: Add ONE call at the very top (after the bypass check): LeadPhoneEntryHandler.beforeSave(...) for before insert / update. Everything else unchanged. | E9: Formatting, duplicate check, round robin and validation rules all see the copied number as today | F9: Medium: LeadTrigger runs for every Lead save; covered by existing LeadTrigger tests + new tests
A10: Existing | B10: Aura Component | C10: NewLeadCmp (Lead New button, desktop + mobile) | D10: In the existing onload step: if the form did not receive Phone__c (user cannot see it), show the entry inputs (required Phone + Secondary Phone) instead. | E10: Users who can see Phone__c: no change. Masked users: same form, entry inputs. | F10: Low
A11: Existing | B11: Aura Component | C11: NewRefLeadCmp (New Referral Lead quick action) | D11: Same as NewLeadCmp | E11: Same | F11: Low
A12: New (update) | B12: Profile | C12: POC Masked Rep | D12: Edit access to the 2 entry fields | E12: POC users can type numbers | F12: None
A13: New (update) | B13: Lightning Page | C13: Sales_Lead_Record_Page_Masked_POC | D13: Add "Secondary Phone" entry field to the details so POC users can add / change the secondary number | E13: POC users only | F13: None
A14: No change | B14: Apex | C14: RelatedSourceHandler, LeadTriggerHandler | D14: Existing formatting + duplicate check keep working on Phone__c | E14: - | F14: -
A15: Deferred to Part 11 | B15: Lightning Page | C15: New_Lead_Page, New_Lead_Page1_sales | D15: Phone fields swapped for panel + entry field at go-live | E15: No change now | F15: -
A16: Unaffected | B16: Integrations | C16: Website / portals / MCube / LeadCreationAPI | D16: Still write Phone__c directly; entry fields not used | E16: No change | F16: -

Sheet Part 5a Plan
A1: Part 5a (v1.5.0) - Calling screens
A2: Explained before implementation; originals in backup/v1.5.0-part5a-pre-change
A4: New / Existing | B4: Type | C4: Component | D4: Change | E4: Effect for users | F4: Risk
A5: New | B5: Apex Class | C5: PhoneDisplayService (+ PhoneDisplayServiceTest) | D5: isMaskedUser(): true when the user cannot read Lead.Phone__c. maskForDisplay(): "+91 9876543221" -> "+91 98XXXXXX21". resolve(recordId, maskedValue, candidates): finds the real number on the server (with sharing) and writes an audit row. | E5: Same masking rule on every screen | F5: Low
A6: New | B6: Custom Field (formula) | C6: Lead.Phone_Masked__c | D6: LEFT 2 + X + RIGHT 2 of Phone__c | E6: Masked number on the call panels | F6: None
A7: Updated (ours) | B7: Apex Class | C7: MaskedDialService | D7: + logAccess(): one audit row per MakeCall / G-Talk dial (deferred when a callout follows) | E7: Every masked call is audited | F7: Low
A8: Existing | B8: Apex Class | C8: MakeCallController | D8: readContacts: masked list for masked users (Lead + Related Source numbers). callCustomer: if the number contains X, find the real one on the server, then call MCube exactly as today. | E8: Current users: no change. Masked users: masked list, call still placed. | F8: Low-medium
A9: Existing | B9: Apex Class | C9: OfflineCallAppAPI | D9: getLeadPhone / getOppPhone: masked for masked users. triggerCall: if the number contains X, find the real one on the server before the G-Talk callout. | E9: Same | F9: Low-medium
A10: Existing | B10: Aura Component | C10: CallPanel, CallPanel_Outbound | D10: Show Phone_Masked__c instead of the blank Phone__c for masked users (detected on load). | E10: Masked users see 98XXXXXX21 instead of an empty line | F10: Low
A11: No change | B11: Aura / LWC | C11: MakeCall, utilityCallComponent, offlineCallQuickActionCmp | D11: They display what Apex returns and send it back; Apex now handles masked values. | E11: - | F11: -
A12: Note | B12: LWC | C12: offlineCallQuickActionCmp | D12: Existing issue found (not changed): treats the getLeadPhone result (a map) as a text number and shows a debug alert. | E12: Report to the owner of this component | F12: -

Sheet Part 5b Plan
A1: Part 5b (v1.5.0) - Call history and logs
A2: Explained before implementation; originals in backup/v1.5.0-part5b-pre-change
A4: New / Existing | B4: Type | C4: Component | D4: Change | E4: Effect for users | F4: Risk
A5: New | B5: Custom Field (formula) | C5: Call_Detail__c.Call_To_Masked__c | D5: Masked customer number of a call (first 2 + last 2) | E5: Masked column for call list views / reports (used at go-live) | F5: None
A6: New | B6: Apex Class (test) | C6: PhoneMaskingHistoryTest | D6: Tests the masked paths of callRecords, GetData and the log masking (callouts mocked) | E6: - | F6: -
A7: Existing | B7: Apex Class | C7: mCubeController.callRecords | D7: For masked users, mask Call_From__c / Call_To__c on the returned call list (in memory, never saved) | E7: Call history list (mCubeLightningPage) shows 98XXXXXX21 for masked users; unchanged for others | F7: Low
